/*
	When an exception is thrown, destructors of the 
	objects (whose scope ends with the try block) is automatically 
	called before the catch block gets exectuted.
*/

